Workbook

Sheet README
A2: Routing policy selection — corrected research evidence
A4: 20 September 2026 | Supervisor workbook | Scientific checkpoint: MODIFY OBSERVER
A7: Question / point | B7: Explanation
A8: Research question | B8: When does adapting an established routing policy improve observed decision quality over a fixed policy?
A9: Current decision | B9: Hold the main experiment and ML. The route-order forecast screen failed despite acceptable selected-path average prediction error.
A10: Completed original pilot | B10: 270 runs, 30 contexts, 3 policies. DTT dominates original time/CO2 context means. Preserved separately.
A11: New completed evidence | B11: 432 development runs and 232 marginal route-probe runs. These are engineering/development evidence, not a final test set.
A12: Start here | B12: Open WEIGHTS; choose an amber context/profile; follow DECISION_MATRIX -> NORMALIZATION -> MCDM_CALCULATION.
A13: Primary MCDM | B13: Fixed-reference additive cost, time + CO2; declared analytical preference profiles. VIKOR is one sensitivity only.
A14: Key forecast finding | B14: Selected-path CO2 WAPE 14.71%; route-probe choice loss 21.62% against best observed route in fixed-replay panels.
A15: Headroom finding | B15: Four policy settings win development contexts; best fixed DTT has mean balanced headroom 0.02980 cost units. This is not an ML gain.
A16: Preference finding | B16: Three two-criterion profiles produce identical winners in all 24 contexts; do not exaggerate the MCDM contribution.
A17: Color / status key | B17: Green: completed observations; blue: formulas; amber: editable assumptions; gray: ungenerated; purple: hypothetical. Text labels also state status.
A18: Mathematical traceability | B18: EQUATIONS_TRACEABILITY gives sources and adaptations; SOURCES states access limits. No invisible invented formula.
... A48: SOURCES | B48: Verified bibliography and access status

Sheet LITERATURE_METHODS
A2: Method choice follows the decision problem
A4: ONE primary method; ONE VIKOR sensitivity. No fictitious TOPSIS/PROMETHEE results.
A7: Method | B7: Primary source | C7: Normalization | D7: Weights | E7: Ranking | F7: Assumptions | G7: Excel difficulty | H7: Role | I7: Why / value | J7: Limitation | K7: Transportation connection
A8: Additive value / SAW | B8: R12,R15,R16 | C8: Value functions; here x / fixed positive reference | D8: Multiply criterion values by nonnegative weights summing to 1 | E8: Minimize weighted sum of costs | F8: Preferential separability; linear compensation over chosen range | G8: Very easy | H8: PRIMARY | I8: Fixed references make cross-context regret interpretable | J8: Changing scale changes trade-off; no elicited stakeholder utility | K8: Transportation appraisal; weighted eco objectives are related, not identical
A9: TOPSIS | B9: R12,R13 | C9: Standard vector normalization within alternative matrix | D9: Weights scale normalized coordinates | E9: Maximize distance from worst / (distance to best + distance to worst) | F9: Euclidean geometry; ideal and worst depend on available alternatives | G9: Easy/moderate | H9: NOT NUMERICALLY ADDED | I9: Useful ideal-solution ranking, but adds little here | J9: Closeness differences across scenarios are not common monetary/value losses | K9: Crisp foundation; R29 transportation uses a fuzzy adaptation
A10: VIKOR | B10: R13; R30 section3.3 eqs7-11 | C10: Best/worst range, direction-aware | D10: Weighted normalized losses; additional v=.5 | E10: Minimize compromise Q; advantage + stability or compromise set | F10: Compromise between aggregate S and largest criterion loss R | G10: Moderate | H10: ONE SECONDARY METHOD | I10: Strong inspectable transport application; explains disagreement | J10: Scenario-dependent range; DQ convention differs between papers; not statistical robustness | K10: Rail alignment selection R30; planning problem differs from pre-trip policy
A11: PROMETHEE II | B11: R14 | C11: No universal normalization; criterion preference functions on pairwise differences | D11: Aggregate preference degrees with weights | E11: Descending positive minus negative preference flow | F11: Preference functions and often indifference/preference thresholds | G11: Moderate/many cells | H11: NOT ADDED | I11: Threshold-based outranking could matter after elicitation | J11: No justified thresholds; usual preference discards magnitude | K11: Walking route application R31
A12: AHP for weights | B12: R28 | C12: Pairwise judgments rather than outcome normalization | D12: Priority vector from actual pairwise comparisons | E12: Supplies weights; consistency assesses judgments | F12: Real judgments required | G12: Moderate | H12: DEFER | I12: Could support future elicitation | J12: No fabricated judgments; consistency is not empirical correctness | K12: Established decision support; not a routing algorithm
A13: Entropy / dispersion weights | B13: Not adopted | C13: Data distribution, often normalized proportions | D13: Weights follow dispersion | E13: Not a complete ranking method | F13: Variation proxies information, not preference | G13: Easy | H13: REJECT FOR PREFERENCES | I13: No need to equate noise/variation with importance | J13: Test-based weighting would leak outcomes | K13: No equation implemented; no stakeholder interpretation

Sheet ROUTING_STRATEGIES
A2: Four objectives; ECO / TECO release remains blocked
A4: Development TECO05/10/15 are parameter settings, not three new policy principles.
A7: Policy | B7: Source | C7: Objective | D7: Inputs | E7: Selection rule | F7: Timing | G7: Traffic information | H7: Environmental information | I7: SUMO adaptation | J7: Expected strength | K7: Limitation | L7: Literature versus adaptation
A8: SP | B8: R01; R05 section 2.3 | C8: Minimize route length | D8: Edge/movement lengths; legal catalogue | E8: argmin over routes of sum length | F8: Static pre-trip | G8: No dynamic data | H8: No | I8: Enumerate all 29 simple legal paths; lexicographic tie | J8: Stable baseline; avoids estimation errors | K8: Ignores congestion and emissions | L8: Literature objective; catalogue enumeration is our implementation
A9: DTT | B9: R03; R05 section 2.3 eq22 with time-only cost; R35 | C9: Minimize estimated in-network time | D9: Last complete 60-s edge/movement snapshot | E9: argmin sum estimated time | F9: Dynamic pre-trip | G9: Same lagged traffic data | H9: No environmental objective | I9: Refresh costs every 60 s; assign at request; no en-route changes | J9: Responds to changing delay | K9: Lag, synchronized diversions and insertion-time staleness | L9: Objective established; native snapshot route sum is our adaptation
A10: ECO | B10: R03; R40; R06 | C10: Minimize estimated in-network tailpipe CO2 | D10: Same snapshot per-vehicle edge emission estimates | E10: argmin sum estimated grams | F10: Dynamic pre-trip | G10: Same information coverage | H10: CO2 estimate | I10: Native CO2_perVeh / 1000 plus internal movement costs | J10: Environmental objective independent of distance/time proxy | K10: Forecast route-order gate failed; not a validated eco-navigation system | L10: Established objective; NOT reproduction of published GMR/SVM
A11: TECO | B11: R04 objective; R05 section2.3 eq23 time-budget concept | C11: Minimize estimated CO2 subject to estimated time budget | D11: ECO and DTT forecasts; allowance alpha | E11: min Ehat where That <= (1+alpha) min That | F11: Dynamic pre-trip | G11: Same information coverage | H11: CO2 estimate | I11: Filter the same 29 routes then minimize grams; 5/10/15% development | J11: Bounds estimated detour and may limit inefficient diversions | K11: No realized time guarantee; alpha not yet finally frozen | L11: Hard finite-candidate constraint is OUR adaptation; Huang uses soft sigmoid weighting

Sheet EQUATIONS_TRACEABILITY
A2: Where each mathematical step comes from
A4: Unretrieved equation numbers are marked unverified; no invented page or equation attribution.
A7: ID | B7: Concept | C7: Source / location | D7: Standard concept | E7: Our adaptation | F7: Code / Excel location | G7: Status
A8: E01 | B8: Minimum additive path cost | C8: Dijkstra R01; Huang R05 sec2.3 | D8: min over legal paths sum edge cost | E8: Length / lagged time / lagged grams replace generic cost; exhaustive catalogue search | F8: src/observer.py choose; ROUTING_STRATEGIES | G8: Objective established; implementation adaptation
A9: E02 | B9: Time-constrained eco objective | C9: Zeng2017 R04 objective; Huang R05 eq23 | D9: Huang tc=(1+epsilon)t* with soft weighting eq22 | E9: min Ehat(p) subject to That(p)<=(1+alpha)min That; hard filter | F9: src/observer.py choose; WORKED_EXAMPLE | G9: Adaptation; not a verbatim Huang equation; Zeng full equation number unverified
A10: E03 | B10: Native per-vehicle emissions | C10: SUMO1.25 source R36; R21 | D10: M_mg / sampled vehicle-seconds * estimated traversal seconds | E10: Divide by1000 and sum external + internal connectors | F10: src/observer.py; forecast_trip_pairs.csv.gz | G10: Native algebra verified; treating sum as future route cost is our forecasting adaptation
A11: E04 | B11: Experienced journey / emission mean | C11: R19,R20; arithmetic definition | D11: duration + departDelay; CO2_abs in mg | E11: Full requested primary cohort; convert grams; average within run then equal seed mean | F11: RAW_PERFORMANCE -> REDESIGN_RESULTS | G11: Our estimand/aggregation; no new estimator invention
A12: E05 | B12: Fixed-reference additive cost | C12: Keeney-Raiffa R15; DCLG R16 | D12: Additive value=sum criterion weights x single-criterion values | E12: Cost C=sum w_k*y_k/a_k, with positive frozen references | F12: NORMALIZATION; MCDM_CALCULATION; =SUM(weighted cells) | G12: Our linear reference-scaling adaptation; lower is preferred
A13: E06 | B13: Decision regret / headroom | C13: Robust optimization R24; algorithm selection R08-R10 | D13: Opportunity loss relative to best feasible alternative | E13: r_sa=C_sa-min_b C_sb; H_s=r_s,fixed | F13: ROBUSTNESS; =chosen_cost-MIN(policy_costs) | G13: Context-policy application; differs from VIKOR max criterion loss
A14: E07 | B14: Mean / minimax fixed | C14: R24; portfolio benchmark R09 | D14: Min expected cost; min worst opportunity loss | E14: Training-context equal mean; min maximum training regret | F14: Future fixed policy selected before validation/test | G14: Finite designed-context approximation, not guarantee beyond design
A15: E08 | B15: VIKOR S and R | C15: Kosijer R30 sec3.3 pp200-201 eqs7,8 | D15: S=sum w*(best-f)/(best-worst); R=max weighted ratio | E15: All cost criteria: (x-min)/(max-min); constant columns contribute0 | F15: MCDM_METHOD_COMPARISON; SUM and MAX | G15: Cost-direction algebra equivalent; zero-range convention explicit
A16: E09 | B16: VIKOR Q and acceptance | C16: Kosijer R30 eqs9-11, p201 | D16: Q=v*scaledS+(1-v)*scaledR; DQ=min(.25,1/(m-1)) | E16: v=.5; stability best S or R or best Q at both .25 and .75 | F16: MCDM_METHOD_COMPARISON; supplementary_analysis.py | G16: Follow inspected source; prior uncapped convention archived separately
A17: E10 | B17: P95 | C17: Hyndman-Fan R27 type7 | D17: h=1+(n-1)p; linear interpolation between order statistics | E17: p=.95 within each complete primary run; equal mean across seeds | F17: np.quantile(method=linear); P95 diagnostic column | G17: Not pooled quantile; pilot original lower order statistic unchanged
A18: E11 | B18: Prediction error screen | C18: Absolute-error arithmetic; decision-loss distinction R11 | D18: MAE=mean abs(pred-actual); WAPE=sum abs error/sum actual | E18: Trip-weighted screen; bias=sum error/sum actual; thresholds declared here | F18: analysis/forecast_summary.csv; VALIDATION | G18: Research tolerances not established acceptance standards
... A21: E14 | B21: TOPSIS / PROMETHEE comparison only | C21: R12,R13 / R14 | D21: Vector distances to ideals / pairwise preference flows | E21: No numeric implementation in this release | F21: LITERATURE_METHODS; report | G21: Avoid extra unexplained methods and unjustified thresholds

Sheet NETWORK
A2: Engineering candidate: compact cross-connected urban mesh
A4: 12 signalized junctions; 47 external links; 29 legal simple primary paths. One topology, no real-city inference.
A7: Candidate | B7: Core junctions | C7: Directed core links | D7: Simple graph paths | E7: Min core length (m) | F7: Max core length (m) | G7: Evidence status
A8: 2x4 | B8: 8 | C8: 20 | D8: 8 | E8: 1200 | F8: 2400 | G8: Analytical graph only; not SUMO-engineered
A9: 3x3 | B9: 9 | C9: 24 | D9: 9 | E9: 800 | F9: 2000 | G9: Analytical graph only; not SUMO-engineered
A10: 3x4 | B10: 12 | C10: 34 | D10: 29 | E10: 1200 | F10: 3200 | G10: SUMO engineering tested
A13: Primary OD | B13: O -> C0 ... C3 -> D
A14: Background | B14: Four fixed NS/SN streams at columns 1 and 2
A15: Signal programs | B15: 60 s; EW/NS 26/26 or 36/16; two 3 s yellow + 1 s all-red
A16: Capacity specification | B16: Lane counts are inputs, not calibrated saturation capacities.
A19: External link | B19: From | C19: To | D19: Lanes | E19: Speed (km/h) | F19: Requested length (m)
A20: C0_C1 | B20: C0 | C20: C1 | D20: 1 | E20: 50 | F20: 400
A21: C0_L0 | B21: C0 | C21: L0 | D21: 1 | E21: 40 | F21: 300
A22: C0_U0 | B22: C0 | C22: U0 | D22: 1 | E22: 40 | F22: 300
A23: C1_C0 | B23: C1 | C23: C0 | D23: 1 | E23: 50 | F23: 400
A24: C1_CR | B24: C1 | C24: CR | D24: 1 | E24: 50 | F24: 150
A25: C1_L1 | B25: C1 | C25: L1 | D25: 1 | E25: 40 | F25: 300
A26: C1_U1 | B26: C1 | C26: U1 | D26: 1 | E26: 40 | F26: 300
A27: C2_C1 | B27: C2 | C27: C1 | D27: 1 | E27: 50 | F27: 400
A28: C2_C3 | B28: C2 | C28: C3 | D28: 1 | E28: 50 | F28: 400
A29: C2_L2 | B29: C2 | C29: L2 | D29: 1 | E29: 40 | F29: 300
A30: C2_U2 | B30: C2 | C30: U2 | D30: 1 | E30: 40 | F30: 300
A31: C3_C2 | B31: C3 | C31: C2 | D31: 1 | E31: 50 | F31: 400
... A66: source | B66: O | C66: C0 | D66: 3 | E66: 50 | F66: 1500
A70: Route | B70: Primary? | C70: Length incl. connectors (m) | D70: External edge sequence
A71: NS1 | B71: NO | C71: 1849.6 | D71: N1_U1 U1_C1 C1_L1 L1_S1
A72: NS2 | B72: NO | C72: 1849.6 | D72: N2_U2 U2_C2 C2_L2 L2_S2
A73: P01 | B73: YES | C73: 3208.82 | D73: source C0_C1 C1_CR CR_C2 C2_C3 sink
A74: P02 | B74: YES | C74: 3833.87 | D74: source C0_C1 C1_CR CR_C2 C2_L2 L2_L3 L3_C3 sink
A75: P03 | B75: YES | C75: 3819.34 | D75: source C0_C1 C1_CR CR_C2 C2_U2 U2_U3 U3_C3 sink
A76: P04 | B76: YES | C76: 3831.78 | D76: source C0_C1 C1_L1 L1_LR LR_L2 L2_C2 C2_C3 sink
A77: P05 | B77: YES | C77: 4447.87 | D77: source C0_C1 C1_L1 L1_LR LR_L2 L2_C2 C2_U2 U2_U3 U3_C3 sink
A78: P06 | B78: YES | C78: 3833.87 | D78: source C0_C1 C1_L1 L1_LR LR_L2 L2_L3 L3_C3 sink
A79: P07 | B79: YES | C79: 3826.48 | D79: source C0_C1 C1_U1 U1_UR UR_U2 U2_C2 C2_C3 sink
A80: P08 | B80: YES | C80: 4457.1 | D80: source C0_C1 C1_U1 U1_UR UR_U2 U2_C2 C2_L2 L2_L3 L3_C3 sink
A81: P09 | B81: YES | C81: 3819.34 | D81: source C0_C1 C1_U1 U1_UR UR_U2 U2_U3 U3_C3 sink
A82: P10 | B82: YES | C82: 3834.13 | D82: source C0_L0 L0_L1 L1_C1 C1_CR CR_C2 C2_C3 sink
... A103: SN2 | B103: NO | C103: 1849.6 | D103: S2_L2 L2_C2 C2_U2 U2_N2

Sheet SCENARIO_DESIGN
A2: Development evidence and unreleased main design
A4: D = completed development; M = preallocated candidate main contexts, outcomes NOT GENERATED.
A7: Context | B7: Primary (veh/h) | C7: Background / stream (veh/h) | D7: Restriction location | E7: Speed ratio | F7: Signal | G7: Allocation | H7: Repetitions | I7: Outcome status | J7: Knowledge at selection
A8: D001 | B8: 720 | C8: 200 | D8: None | E8: 1 | F8: Balanced | G8: DEVELOPMENT | H8: 3 | I8: COMPLETED | J8: Scheduled/stipulated inputs
A9: D002 | B9: 720 | C9: 200 | D9: None | E9: 1 | F9: Arterial | G9: DEVELOPMENT | H9: 3 | I9: COMPLETED | J9: Scheduled/stipulated inputs
A10: D003 | B10: 720 | C10: 200 | D10: U | E10: 0.35 | F10: Balanced | G10: DEVELOPMENT | H10: 3 | I10: COMPLETED | J10: Scheduled/stipulated inputs
A11: D004 | B11: 720 | C11: 200 | D11: U | E11: 0.35 | F11: Arterial | G11: DEVELOPMENT | H11: 3 | I11: COMPLETED | J11: Scheduled/stipulated inputs
A12: D005 | B12: 720 | C12: 200 | D12: C | E12: 0.35 | F12: Balanced | G12: DEVELOPMENT | H12: 3 | I12: COMPLETED | J12: Scheduled/stipulated inputs
A13: D006 | B13: 720 | C13: 200 | D13: C | E13: 0.35 | F13: Arterial | G13: DEVELOPMENT | H13: 3 | I13: COMPLETED | J13: Scheduled/stipulated inputs
A14: D007 | B14: 720 | C14: 200 | D14: L | E14: 0.35 | F14: Balanced | G14: DEVELOPMENT | H14: 3 | I14: COMPLETED | J14: Scheduled/stipulated inputs
A15: D008 | B15: 720 | C15: 200 | D15: L | E15: 0.35 | F15: Arterial | G15: DEVELOPMENT | H15: 3 | I15: COMPLETED | J15: Scheduled/stipulated inputs
A16: D009 | B16: 1200 | C16: 200 | D16: None | E16: 1 | F16: Balanced | G16: DEVELOPMENT | H16: 3 | I16: COMPLETED | J16: Scheduled/stipulated inputs
A17: D010 | B17: 1200 | C17: 200 | D17: None | E17: 1 | F17: Arterial | G17: DEVELOPMENT | H17: 3 | I17: COMPLETED | J17: Scheduled/stipulated inputs
A18: D011 | B18: 1200 | C18: 200 | D18: U | E18: 0.35 | F18: Balanced | G18: DEVELOPMENT | H18: 3 | I18: COMPLETED | J18: Scheduled/stipulated inputs
A19: D012 | B19: 1200 | C19: 200 | D19: U | E19: 0.35 | F19: Arterial | G19: DEVELOPMENT | H19: 3 | I19: COMPLETED | J19: Scheduled/stipulated inputs
... A171: M140 | B171: 1680 | C171: 280 | D171: L | E171: 0.65 | F171: Arterial | G171: VALIDATION | H171: 5 | I171: TO BE GENERATED — BLOCKED | J171: Scheduled/stipulated inputs

Sheet RAW_PERFORMANCE
A2: 432 completed development runs
A4: Imported audited SUMO run summaries; primary cohort only in primary criteria. Not a held-out test.
A7: Key | B7: Context | C7: Setting | D7: Seed | E7: Primary n | F7: Mean journey (s) | G7: CO2 (g/veh) | H7: Distance (m) | I7: P95 journey (s) | J7: Insertion (s) | K7: BG journey (s) | L7: BG CO2 (g/veh) | M7: Network cohort CO2 (g) | N7: Stopped vehicle-time (veh-s) | O7: Default link fraction | P7: CO2 WAPE | Q7: CO2 signed bias | R7: Mean primary (veh/h) | S7: Background / stream | T7: Restriction | U7: Signal | V7: Source status | W7: Native mass error
A8: D001__SP__8101 | B8: D001 | C8: SP | D8: 8101 | E8: 375 | F8: 336.71733 | G8: 906.09468 | H8: 3203.72 | I8: 356 | J8: 0.098666667 | K8: 236.98677 | L8: 578.68636 | M8: 558528.95 | N8: 78535 | O8: 0 | P8: 0.046665366 | Q8: 0.015033588 | R8: 720 | S8: 200 | T8: None | U8: Balanced | V8: NEW DEVELOPMENT RESULT | W8: 0.0014515402
A9: D001__SP__8102 | B9: D001 | C9: SP | D9: 8102 | E9: 392 | F9: 337.48724 | G9: 910.74976 | H9: 3203.72 | I9: 357 | J9: 0.125 | K9: 238.77778 | L9: 583.98384 | M9: 583015.65 | N9: 78516 | O9: 0 | P9: 0.042920982 | Q9: 0.0041563173 | R9: 720 | S9: 200 | T9: None | U9: Balanced | V9: NEW DEVELOPMENT RESULT | W9: 0.0014535984
A10: D001__SP__8103 | B10: D001 | C10: SP | D10: 8103 | E10: 361 | F10: 336.70914 | G10: 906.86264 | H10: 3203.72 | I10: 356 | J10: 0.14127424 | K10: 237.02757 | L10: 579.23196 | M10: 558490.97 | N10: 75179 | O10: 0 | P10: 0.043290611 | Q10: 0.0053161341 | R10: 720 | S10: 200 | T10: None | U10: Balanced | V10: NEW DEVELOPMENT RESULT | W10: 0.001470761
A11: D001__DTT__8101 | B11: D001 | C11: DTT | D11: 8101 | E11: 375 | F11: 368.41333 | G11: 979.3579 | H11: 3635.1293 | I11: 426 | J11: 0.098666667 | K11: 236.98677 | L11: 578.68636 | M11: 586002.66 | N11: 73009 | O11: 0.75971059 | P11: 0.18294275 | Q11: 0.15713598 | R11: 720 | S11: 200 | T11: None | U11: Balanced | V11: NEW DEVELOPMENT RESULT | W11: 0.001376046
A12: D001__DTT__8102 | B12: D001 | C12: DTT | D12: 8102 | E12: 392 | F12: 373.07143 | G12: 990.25633 | H12: 3629.6059 | I12: 441.45 | J12: 0.125 | K12: 238.77778 | L12: 583.98384 | M12: 614182.23 | N12: 73747 | O12: 0.78395062 | P12: 0.17703479 | Q12: 0.13648927 | R12: 720 | S12: 200 | T12: None | U12: Balanced | V12: NEW DEVELOPMENT RESULT | W12: 0.0013839282
A13: D001__DTT__8103 | B13: D001 | C13: DTT | D13: 8103 | E13: 361 | F13: 360.93352 | G13: 958.80462 | H13: 3634.4145 | I13: 412 | J13: 0.14127424 | K13: 237.02757 | L13: 579.23196 | M13: 577242.02 | N13: 67872 | O13: 0.76121763 | P13: 0.17015345 | Q13: 0.14789195 | R13: 720 | S13: 200 | T13: None | U13: Balanced | V13: NEW DEVELOPMENT RESULT | W13: 0.0014196907
A14: D001__ECO__8101 | B14: D001 | C14: ECO | D14: 8101 | E14: 375 | F14: 336.71733 | G14: 906.09468 | H14: 3203.72 | I14: 356 | J14: 0.098666667 | K14: 236.98677 | L14: 578.68636 | M14: 558528.95 | N14: 78535 | O14: 0 | P14: 0.046665366 | Q14: 0.015033588 | R14: 720 | S14: 200 | T14: None | U14: Balanced | V14: NEW DEVELOPMENT RESULT | W14: 0.0014515402
A15: D001__ECO__8102 | B15: D001 | C15: ECO | D15: 8102 | E15: 392 | F15: 337.48724 | G15: 910.74976 | H15: 3203.72 | I15: 357 | J15: 0.125 | K15: 238.77778 | L15: 583.98384 | M15: 583015.65 | N15: 78516 | O15: 0 | P15: 0.042920982 | Q15: 0.0041563173 | R15: 720 | S15: 200 | T15: None | U15: Balanced | V15: NEW DEVELOPMENT RESULT | W15: 0.0014535984
A16: D001__ECO__8103 | B16: D001 | C16: ECO | D16: 8103 | E16: 361 | F16: 336.70914 | G16: 906.86264 | H16: 3203.72 | I16: 356 | J16: 0.14127424 | K16: 237.02757 | L16: 579.23196 | M16: 558490.97 | N16: 75179 | O16: 0 | P16: 0.043290611 | Q16: 0.0053161341 | R16: 720 | S16: 200 | T16: None | U16: Balanced | V16: NEW DEVELOPMENT RESULT | W16: 0.001470761
A17: D001__TECO05__8101 | B17: D001 | C17: TECO05 | D17: 8101 | E17: 375 | F17: 360.816 | G17: 971.24918 | H17: 3594.5123 | I17: 410.3 | J17: 0.098666667 | K17: 237.01323 | L17: 578.73581 | M17: 582980.58 | N17: 73371 | O17: 0.63325518 | P17: 0.17551735 | Q17: 0.12773761 | R17: 720 | S17: 200 | T17: None | U17: Balanced | V17: NEW DEVELOPMENT RESULT | W17: 0.0013588955
A18: D001__TECO05__8102 | B18: D001 | C18: TECO05 | D18: 8102 | E18: 392 | F18: 362.82143 | G18: 976.51474 | H18: 3585.0584 | I18: 425.45 | J18: 0.125 | K18: 238.77778 | L18: 583.98384 | M18: 608795.52 | N18: 73510 | O18: 0.67128157 | P18: 0.15799372 | Q18: 0.10012674 | R18: 720 | S18: 200 | T18: None | U18: Balanced | V18: NEW DEVELOPMENT RESULT | W18: 0.0013743567
A19: D001__TECO05__8103 | B19: D001 | C19: TECO05 | D19: 8103 | E19: 361 | F19: 358.09972 | G19: 965.17577 | H19: 3590.8241 | I19: 400 | J19: 0.14127424 | K19: 237.04261 | L19: 579.26789 | M19: 579556.34 | N19: 69669 | O19: 0.6590124 | P19: 0.14749955 | Q19: 0.10384628 | R19: 720 | S19: 200 | T19: None | U19: Balanced | V19: NEW DEVELOPMENT RESULT | W19: 0.0013881113
... A439: D024__TECO15__8103 | B439: D024 | C439: TECO15 | D439: 8103 | E439: 862 | F439: 663.67749 | G439: 1489.7032 | H439: 3203.72 | I439: 953.95 | J439: 133.43387 | K439: 247.02757 | L439: 607.67642 | M439: 1526587.1 | N439: 248772 | O439: 0 | P439: 0.12076377 | Q439: -0.0014328132 | R439: 1680 | S439: 200 | T439: L | U439: Arterial | V439: NEW DEVELOPMENT RESULT | W439: 0.00097854461

Sheet CRITERIA_SELECTION
A2: Two primary criteria; additional measures remain diagnostics
A4: Primary time + CO2; distance and P95 are available for explicitly labeled sensitivity.
A7: Criterion | B7: Role | C7: Unit / population | D7: Direction | E7: Calculation | F7: Source | G7: Meaning | H7: Redundancy / limitation | I7: Decision
A8: Mean journey time | B8: ESTABLISHED; PRIMARY | C8: s/primary vehicle | D8: Cost | E8: arrival minus scheduled request = duration + departDelay | F8: R19 SUMO Tripinfo; our full-cohort definition | G8: Captures service including delayed insertion | H8: Partly correlated with CO2, but a distinct mobility impact | I8: KEEP
A9: Mean tailpipe CO2 | B9: ESTABLISHED; PRIMARY | C9: g/primary vehicle | D9: Cost | E9: CO2_abs mg / 1000; completed primary cohort mean | F9: R20-R21; R03,R06,R40 environmental routing | G9: Direct modeled environmental outcome | H9: Excludes pre-insertion idling, lifecycle and non-CO2 pollutants | I9: KEEP
A10: Fuel | B10: ESTABLISHED environmental alternative | C10: SUMO model fuel units | D10: Cost | E10: Native fuel_abs, unit mode recorded | F10: R05; R20 | G10: Energy relevance | H10: CO2/fuel ratio ~3.135; trip correlation >0.999999997 in every run | I10: REMOVE from MCDM
A11: Distance | B11: ESTABLISHED route objective; possible decision criterion | C11: m/primary vehicle | D11: Cost | E11: Tripinfo routeLength | F11: R01,R05; R19 | G11: Could represent distance-related operating burden if explicitly valued | H11: Not automatically double counting SP; but no separate stakeholder value stated; 0/24 winner changes | I11: DIAGNOSTIC
A12: P95 journey time | B12: ADDITIONAL tail service criterion | C12: s/primary vehicle | D12: Cost | E12: Type7 per-run percentile; average of run P95s across seeds | F12: R17; R27; our episode-tail adaptation | G12: Reflects poorly served trips | H12: Not day-to-day same-trip reliability; correlated with mean; only 1/24 equal-three-weight winner changes | I12: SENSITIVITY
A13: Delay / time loss | B13: ADDITIONAL operational indicator | C13: s/vehicle | D13: Cost | E13: Native timeLoss / waitingTime; definitions differ | F13: R19 | G13: Explains mechanisms | H13: Adds another time-related component; do not silently equate waiting, timeLoss and departDelay | I13: DIAGNOSTIC
A14: Stops / queues | B14: ADDITIONAL operational indicator | C14: count; vehicle-s | D14: Cost | E14: Stops require threshold convention; edge waitingTime aggregated | F14: R22 | G14: Locates bottlenecks and spillback | H14: Not an independent welfare criterion; queue proxy is stopped vehicle-time, not max physical length | I14: DIAGNOSTIC
A15: Safety / exposure / noise / money | B15: Additional possible impacts | C15: Unspecified | D15: Unspecified | E15: No validated model supplied | F15: Not used | G15: Potential future studies | H15: Cannot be inferred credibly from present outputs | I15: REMOVE

Sheet DECISION_MATRIX
A2: 1. Observed policy outcomes for the selected context
A4: Only observed development outcomes enter physical ranking. Future ML predictions will be separate.
A5: Development context | B5: =WEIGHTS!B5 | D5: Preference profile | E5: =WEIGHTS!B6
A7: Policy | B7: Time (s) — COST | C7: CO2 (g) — COST | D7: Distance (m) — COST | E7: P95 (s) — COST | F7: Evidence status | G7: Source lookup
A8: SP | B8: =INDEX(REDESIGN_RESULTS!$D$8:$D$151,MATCH(WEIGHTS!$B$5&"__"&A8,REDESIGN_RESULTS!$A$8:$A$151,0)) | C8: =INDEX(REDESIGN_RESULTS!$E$8:$E$151,MATCH(WEIGHTS!$B$5&"__"&A8,REDESIGN_RESULTS!$A$8:$A$151,0)) | D8: =INDEX(REDESIGN_RESULTS!$F$8:$F$151,MATCH(WEIGHTS!$B$5&"__"&A8,REDESIGN_RESULTS!$A$8:$A$151,0)) | E8: =INDEX(REDESIGN_RESULTS!$G$8:$G$151,MATCH(WEIGHTS!$B$5&"__"&A8,REDESIGN_RESULTS!$A$8:$A$151,0)) | F8: COMPLETED DEVELOPMENT | G8: =WEIGHTS!B5&"__"&A8
A9: DTT | B9: =INDEX(REDESIGN_RESULTS!$D$8:$D$151,MATCH(WEIGHTS!$B$5&"__"&A9,REDESIGN_RESULTS!$A$8:$A$151,0)) | C9: =INDEX(REDESIGN_RESULTS!$E$8:$E$151,MATCH(WEIGHTS!$B$5&"__"&A9,REDESIGN_RESULTS!$A$8:$A$151,0)) | D9: =INDEX(REDESIGN_RESULTS!$F$8:$F$151,MATCH(WEIGHTS!$B$5&"__"&A9,REDESIGN_RESULTS!$A$8:$A$151,0)) | E9: =INDEX(REDESIGN_RESULTS!$G$8:$G$151,MATCH(WEIGHTS!$B$5&"__"&A9,REDESIGN_RESULTS!$A$8:$A$151,0)) | F9: COMPLETED DEVELOPMENT | G9: =WEIGHTS!B5&"__"&A9
A10: ECO | B10: =INDEX(REDESIGN_RESULTS!$D$8:$D$151,MATCH(WEIGHTS!$B$5&"__"&A10,REDESIGN_RESULTS!$A$8:$A$151,0)) | C10: =INDEX(REDESIGN_RESULTS!$E$8:$E$151,MATCH(WEIGHTS!$B$5&"__"&A10,REDESIGN_RESULTS!$A$8:$A$151,0)) | D10: =INDEX(REDESIGN_RESULTS!$F$8:$F$151,MATCH(WEIGHTS!$B$5&"__"&A10,REDESIGN_RESULTS!$A$8:$A$151,0)) | E10: =INDEX(REDESIGN_RESULTS!$G$8:$G$151,MATCH(WEIGHTS!$B$5&"__"&A10,REDESIGN_RESULTS!$A$8:$A$151,0)) | F10: COMPLETED DEVELOPMENT | G10: =WEIGHTS!B5&"__"&A10
A11: TECO10 | B11: =INDEX(REDESIGN_RESULTS!$D$8:$D$151,MATCH(WEIGHTS!$B$5&"__"&A11,REDESIGN_RESULTS!$A$8:$A$151,0)) | C11: =INDEX(REDESIGN_RESULTS!$E$8:$E$151,MATCH(WEIGHTS!$B$5&"__"&A11,REDESIGN_RESULTS!$A$8:$A$151,0)) | D11: =INDEX(REDESIGN_RESULTS!$F$8:$F$151,MATCH(WEIGHTS!$B$5&"__"&A11,REDESIGN_RESULTS!$A$8:$A$151,0)) | E11: =INDEX(REDESIGN_RESULTS!$G$8:$G$151,MATCH(WEIGHTS!$B$5&"__"&A11,REDESIGN_RESULTS!$A$8:$A$151,0)) | F11: COMPLETED DEVELOPMENT | G11: =WEIGHTS!B5&"__"&A11
A14: Population | B14: Primary requests 600–2400 s, followed until arrival.
A16: MCDM direction | B16: All criteria are costs. Only positive active weights contribute.

Sheet NORMALIZATION
A2: 2. Divide each criterion by its reference
A4: Fixed references retain common loss units across contexts. This is our additive-value scaling adaptation.
A5: Development context | B5: =WEIGHTS!B5 | D5: Preference profile | E5: =WEIGHTS!B6
A7: Policy | B7: Raw T | C7: T reference | D7: Normalized T | E7: Raw CO2 | F7: CO2 reference | G7: Normalized CO2 | H7: Raw distance | I7: Distance ref | J7: Normalized distance | K7: Raw P95 | L7: P95 reference | M7: Normalized P95 | N7: What it means
A8: =DECISION_MATRIX!A8 | B8: =DECISION_MATRIX!B8 | C8: =WEIGHTS!B22 | D8: =B8/C8 | E8: =DECISION_MATRIX!C8 | F8: =WEIGHTS!C22 | G8: =E8/F8 | H8: =DECISION_MATRIX!D8 | I8: =WEIGHTS!D22 | J8: =H8/I8 | K8: =DECISION_MATRIX!E8 | L8: =WEIGHTS!E22 | M8: =K8/L8 | N8: A value of 1 equals the common development reference; >1 is a larger cost.
A9: =DECISION_MATRIX!A9 | B9: =DECISION_MATRIX!B9 | C9: =WEIGHTS!B22 | D9: =B9/C9 | E9: =DECISION_MATRIX!C9 | F9: =WEIGHTS!C22 | G9: =E9/F9 | H9: =DECISION_MATRIX!D9 | I9: =WEIGHTS!D22 | J9: =H9/I9 | K9: =DECISION_MATRIX!E9 | L9: =WEIGHTS!E22 | M9: =K9/L9 | N9: A value of 1 equals the common development reference; >1 is a larger cost.
A10: =DECISION_MATRIX!A10 | B10: =DECISION_MATRIX!B10 | C10: =WEIGHTS!B22 | D10: =B10/C10 | E10: =DECISION_MATRIX!C10 | F10: =WEIGHTS!C22 | G10: =E10/F10 | H10: =DECISION_MATRIX!D10 | I10: =WEIGHTS!D22 | J10: =H10/I10 | K10: =DECISION_MATRIX!E10 | L10: =WEIGHTS!E22 | M10: =K10/L10 | N10: A value of 1 equals the common development reference; >1 is a larger cost.
A11: =DECISION_MATRIX!A11 | B11: =DECISION_MATRIX!B11 | C11: =WEIGHTS!B22 | D11: =B11/C11 | E11: =DECISION_MATRIX!C11 | F11: =WEIGHTS!C22 | G11: =E11/F11 | H11: =DECISION_MATRIX!D11 | I11: =WEIGHTS!D22 | J11: =H11/I11 | K11: =DECISION_MATRIX!E11 | L11: =WEIGHTS!E22 | M11: =K11/L11 | N11: A value of 1 equals the common development reference; >1 is a larger cost.
A15: Example formula | B15: =B8/C8
A17: Original source | B17: Additive value R15/R16; fixed ratio value function is our disclosed adaptation.

Sheet WEIGHTS
A2: The control panel: context, profile and references
A4: Amber cells are editable analytical assumptions; profiles are NOT elicited stakeholder preferences.
A5: Active context | B5: D011
A6: Active profile | B6: Balanced
A9: Declared profile | B9: Time | C9: CO2 | D9: Distance | E9: P95 | F9: Weight sum
A10: Balanced | B10: 0.5 | C10: 0.5 | D10: 0 | E10: 0 | F10: =SUM(B10:E10)
A11: Time-heavy | B11: 0.75 | C11: 0.25 | D11: 0 | E11: 0 | F11: =SUM(B11:E11)
A12: Environment-heavy | B12: 0.25 | C12: 0.75 | D12: 0 | E12: 0 | F12: =SUM(B12:E12)
A13: Distance-set | B13: 0.33333333 | C13: 0.33333333 | D13: 0.33333333 | E13: 0 | F13: =SUM(B13:E13)
A14: Tail-set | B14: 0.33333333 | C14: 0.33333333 | D14: 0 | E14: 0.33333333 | F14: =SUM(B14:E14)
A15: Tail-heavy | B15: 0.2 | C15: 0.2 | D15: 0 | E15: 0.6 | F15: =SUM(B15:E15)
A18: Active values | B18: Time | C18: CO2 | D18: Distance | E18: P95 | F18: Check
A19: Active weights | B19: =INDEX(B10:B15,MATCH($B$6,$A$10:$A$15,0)) | C19: =INDEX(C10:C15,MATCH($B$6,$A$10:$A$15,0)) | D19: =INDEX(D10:D15,MATCH($B$6,$A$10:$A$15,0)) | E19: =INDEX(E10:E15,MATCH($B$6,$A$10:$A$15,0)) | F19: =IF(AND(ABS(SUM(B19:E19)-1)<0.000000001,MIN(B19:E19)>=0),"OK","INVALID")
A22: Development references | B22: =SUMIF(REDESIGN_RESULTS!$H$8:$H$151,1,REDESIGN_RESULTS!$D$8:$D$151)/COUNTIF(REDESIGN_RESULTS!$H$8:$H$151,1) | C22: =SUMIF(REDESIGN_RESULTS!$H$8:$H$151,1,REDESIGN_RESULTS!$E$8:$E$151)/COUNTIF(REDESIGN_RESULTS!$H$8:$H$151,1) | D22: =SUMIF(REDESIGN_RESULTS!$H$8:$H$151,1,REDESIGN_RESULTS!$F$8:$F$151)/COUNTIF(REDESIGN_RESULTS!$H$8:$H$151,1) | E22: =SUMIF(REDESIGN_RESULTS!$H$8:$H$151,1,REDESIGN_RESULTS!$G$8:$G$151)/COUNTIF(REDESIGN_RESULTS!$H$8:$H$151,1)
A24: Reference meaning | B24: Equal mean over 24 x 4 development policy-context means; NOT final training scaling.
A26: Tie tolerance | B26: 1e-10
A27: Near-best tolerance | B27: 0.02 | C27: Illustrative loss units; inspect .01/.02/.05; not an elicited meaningful threshold.
A29: Primary recommendation | B29: Time + CO2. Distance/P95 profiles are development sensitivity only.
A31: VIKOR convention | B31: Kosijer eq11: min(0.25, 1/(m-1)); v=0.5; compare compromise sets.
A33: Scale caveat | B33: Cost increment per physical unit = weight/reference; weights alone do not state trade-offs.

Sheet MCDM_CALCULATION
A2: 3. Weight, add, rank, choose and calculate regret
A4: Smaller additive cost is preferred. All calculations remain visible and traceable.
A5: Development context | B5: =WEIGHTS!B5 | D5: Preference profile | E5: =WEIGHTS!B6
A7: Policy | B7: Norm time | C7: Norm CO2 | D7: Norm distance | E7: Norm P95 | F7: w time | G7: w CO2 | H7: w distance | I7: w P95 | J7: Contribution T | K7: Contribution CO2 | L7: Contribution distance | M7: Contribution P95 | N7: Final cost
A8: =DECISION_MATRIX!A8 | B8: =NORMALIZATION!D8 | C8: =NORMALIZATION!G8 | D8: =NORMALIZATION!J8 | E8: =NORMALIZATION!M8 | F8: =WEIGHTS!B19 | G8: =WEIGHTS!C19 | H8: =WEIGHTS!D19 | I8: =WEIGHTS!E19 | J8: =B8*F8 | K8: =C8*G8 | L8: =D8*H8 | M8: =E8*I8 | N8: =IF(WEIGHTS!F19="OK",SUM(J8:M8),"INVALID WEIGHTS")
A9: =DECISION_MATRIX!A9 | B9: =NORMALIZATION!D9 | C9: =NORMALIZATION!G9 | D9: =NORMALIZATION!J9 | E9: =NORMALIZATION!M9 | F9: =WEIGHTS!B19 | G9: =WEIGHTS!C19 | H9: =WEIGHTS!D19 | I9: =WEIGHTS!E19 | J9: =B9*F9 | K9: =C9*G9 | L9: =D9*H9 | M9: =E9*I9 | N9: =IF(WEIGHTS!F19="OK",SUM(J9:M9),"INVALID WEIGHTS")
A10: =DECISION_MATRIX!A10 | B10: =NORMALIZATION!D10 | C10: =NORMALIZATION!G10 | D10: =NORMALIZATION!J10 | E10: =NORMALIZATION!M10 | F10: =WEIGHTS!B19 | G10: =WEIGHTS!C19 | H10: =WEIGHTS!D19 | I10: =WEIGHTS!E19 | J10: =B10*F10 | K10: =C10*G10 | L10: =D10*H10 | M10: =E10*I10 | N10: =IF(WEIGHTS!F19="OK",SUM(J10:M10),"INVALID WEIGHTS")
A11: =DECISION_MATRIX!A11 | B11: =NORMALIZATION!D11 | C11: =NORMALIZATION!G11 | D11: =NORMALIZATION!J11 | E11: =NORMALIZATION!M11 | F11: =WEIGHTS!B19 | G11: =WEIGHTS!C19 | H11: =WEIGHTS!D19 | I11: =WEIGHTS!E19 | J11: =B11*F11 | K11: =C11*G11 | L11: =D11*H11 | M11: =E11*I11 | N11: =IF(WEIGHTS!F19="OK",SUM(J11:M11),"INVALID WEIGHTS")
A15: Policy | B15: Final cost | C15: Numerical rank | D15: Regret | E15: Near-best?
A16: =A8 | B16: =N8 | C16: =COUNTIF($B$16:$B$19,"<"&(B16-WEIGHTS!$B$26))+1 | D16: =B16-MIN($B$16:$B$19) | E16: =IF(D16<=WEIGHTS!$B$27,"YES","NO")
A17: =A9 | B17: =N9 | C17: =COUNTIF($B$16:$B$19,"<"&(B17-WEIGHTS!$B$26))+1 | D17: =B17-MIN($B$16:$B$19) | E17: =IF(D17<=WEIGHTS!$B$27,"YES","NO")
A18: =A10 | B18: =N10 | C18: =COUNTIF($B$16:$B$19,"<"&(B18-WEIGHTS!$B$26))+1 | D18: =B18-MIN($B$16:$B$19) | E18: =IF(D18<=WEIGHTS!$B$27,"YES","NO")
A19: =A11 | B19: =N11 | C19: =COUNTIF($B$16:$B$19,"<"&(B19-WEIGHTS!$B$26))+1 | D19: =B19-MIN($B$16:$B$19) | E19: =IF(D19<=WEIGHTS!$B$27,"YES","NO")
A22: Selected policy | B22: =INDEX(A16:A19,MATCH(MIN(C16:C19),C16:C19,0))
A24: Score formula | B24: =SUM(J8:M8)
A26: Regret formula | B26: =B16-MIN($B$16:$B$19)
A28: Tie rule | B28: First declared policy among numerical rank 1; near-best is separately defined.

Sheet MCDM_METHOD_COMPARISON
A2: VIKOR sensitivity: follow the actual cited variant
A4: Kosijer et al. 2012, §3.3, eqs7–11. This is within-context compromise ranking, not common-scale scenario regret.
A5: Development context | B5: =WEIGHTS!B5 | D5: Preference profile | E5: =WEIGHTS!B6
A7: Policy | B7: Weighted loss T | C7: Weighted loss CO2 | D7: Weighted loss distance | E7: Weighted loss P95 | F7: S sum | G7: R maximum | H7: Scaled S | I7: Scaled R | J7: Q v=.5 | K7: Q v=.25 | L7: Q v=.75 | M7: Q rank
A8: =DECISION_MATRIX!A8 | B8: =IF(MAX(DECISION_MATRIX!$B$8:$B$11)=MIN(DECISION_MATRIX!$B$8:$B$11),0,(DECISION_MATRIX!B8-MIN(DECISION_MATRIX!$B$8:$B$11))/(MAX(DECISION_MATRIX!$B$8:$B$11)-MIN(DECISION_MATRIX!$B$8:$B$11))*WEIGHTS!B19) | C8: =IF(MAX(DECISION_MATRIX!$C$8:$C$11)=MIN(DECISION_MATRIX!$C$8:$C$11),0,(DECISION_MATRIX!C8-MIN(DECISION_MATRIX!$C$8:$C$11))/(MAX(DECISION_MATRIX!$C$8:$C$11)-MIN(DECISION_MATRIX!$C$8:$C$11))*WEIGHTS!C19) | D8: =IF(MAX(DECISION_MATRIX!$D$8:$D$11)=MIN(DECISION_MATRIX!$D$8:$D$11),0,(DECISION_MATRIX!D8-MIN(DECISION_MATRIX!$D$8:$D$11))/(MAX(DECISION_MATRIX!$D$8:$D$11)-MIN(DECISION_MATRIX!$D$8:$D$11))*WEIGHTS!D19) | E8: =IF(MAX(DECISION_MATRIX!$E$8:$E$11)=MIN(DECISION_MATRIX!$E$8:$E$11),0,(DECISION_MATRIX!E8-MIN(DECISION_MATRIX!$E$8:$E$11))/(MAX(DECISION_MATRIX!$E$8:$E$11)-MIN(DECISION_MATRIX!$E$8:$E$11))*WEIGHTS!E19) | F8: =SUM(B8:E8) | G8: =MAX(B8:E8) | H8: =IF(MAX($F$8:$F$11)=MIN($F$8:$F$11),0,(F8-MIN($F$8:$F$11))/(MAX($F$8:$F$11)-MIN($F$8:$F$11))) | I8: =IF(MAX($G$8:$G$11)=MIN($G$8:$G$11),0,(G8-MIN($G$8:$G$11))/(MAX($G$8:$G$11)-MIN($G$8:$G$11))) | J8: =0.5*H8+0.5*I8 | K8: =0.25*H8+0.75*I8 | L8: =0.75*H8+0.25*I8 | M8: =COUNTIF($J$8:$J$11,"<"&J8)+1
A9: =DECISION_MATRIX!A9 | B9: =IF(MAX(DECISION_MATRIX!$B$8:$B$11)=MIN(DECISION_MATRIX!$B$8:$B$11),0,(DECISION_MATRIX!B9-MIN(DECISION_MATRIX!$B$8:$B$11))/(MAX(DECISION_MATRIX!$B$8:$B$11)-MIN(DECISION_MATRIX!$B$8:$B$11))*WEIGHTS!B19) | C9: =IF(MAX(DECISION_MATRIX!$C$8:$C$11)=MIN(DECISION_MATRIX!$C$8:$C$11),0,(DECISION_MATRIX!C9-MIN(DECISION_MATRIX!$C$8:$C$11))/(MAX(DECISION_MATRIX!$C$8:$C$11)-MIN(DECISION_MATRIX!$C$8:$C$11))*WEIGHTS!C19) | D9: =IF(MAX(DECISION_MATRIX!$D$8:$D$11)=MIN(DECISION_MATRIX!$D$8:$D$11),0,(DECISION_MATRIX!D9-MIN(DECISION_MATRIX!$D$8:$D$11))/(MAX(DECISION_MATRIX!$D$8:$D$11)-MIN(DECISION_MATRIX!$D$8:$D$11))*WEIGHTS!D19) | E9: =IF(MAX(DECISION_MATRIX!$E$8:$E$11)=MIN(DECISION_MATRIX!$E$8:$E$11),0,(DECISION_MATRIX!E9-MIN(DECISION_MATRIX!$E$8:$E$11))/(MAX(DECISION_MATRIX!$E$8:$E$11)-MIN(DECISION_MATRIX!$E$8:$E$11))*WEIGHTS!E19) | F9: =SUM(B9:E9) | G9: =MAX(B9:E9) | H9: =IF(MAX($F$8:$F$11)=MIN($F$8:$F$11),0,(F9-MIN($F$8:$F$11))/(MAX($F$8:$F$11)-MIN($F$8:$F$11))) | I9: =IF(MAX($G$8:$G$11)=MIN($G$8:$G$11),0,(G9-MIN($G$8:$G$11))/(MAX($G$8:$G$11)-MIN($G$8:$G$11))) | J9: =0.5*H9+0.5*I9 | K9: =0.25*H9+0.75*I9 | L9: =0.75*H9+0.25*I9 | M9: =COUNTIF($J$8:$J$11,"<"&J9)+1
A10: =DECISION_MATRIX!A10 | B10: =IF(MAX(DECISION_MATRIX!$B$8:$B$11)=MIN(DECISION_MATRIX!$B$8:$B$11),0,(DECISION_MATRIX!B10-MIN(DECISION_MATRIX!$B$8:$B$11))/(MAX(DECISION_MATRIX!$B$8:$B$11)-MIN(DECISION_MATRIX!$B$8:$B$11))*WEIGHTS!B19) | C10: =IF(MAX(DECISION_MATRIX!$C$8:$C$11)=MIN(DECISION_MATRIX!$C$8:$C$11),0,(DECISION_MATRIX!C10-MIN(DECISION_MATRIX!$C$8:$C$11))/(MAX(DECISION_MATRIX!$C$8:$C$11)-MIN(DECISION_MATRIX!$C$8:$C$11))*WEIGHTS!C19) | D10: =IF(MAX(DECISION_MATRIX!$D$8:$D$11)=MIN(DECISION_MATRIX!$D$8:$D$11),0,(DECISION_MATRIX!D10-MIN(DECISION_MATRIX!$D$8:$D$11))/(MAX(DECISION_MATRIX!$D$8:$D$11)-MIN(DECISION_MATRIX!$D$8:$D$11))*WEIGHTS!D19) | E10: =IF(MAX(DECISION_MATRIX!$E$8:$E$11)=MIN(DECISION_MATRIX!$E$8:$E$11),0,(DECISION_MATRIX!E10-MIN(DECISION_MATRIX!$E$8:$E$11))/(MAX(DECISION_MATRIX!$E$8:$E$11)-MIN(DECISION_MATRIX!$E$8:$E$11))*WEIGHTS!E19) | F10: =SUM(B10:E10) | G10: =MAX(B10:E10) | H10: =IF(MAX($F$8:$F$11)=MIN($F$8:$F$11),0,(F10-MIN($F$8:$F$11))/(MAX($F$8:$F$11)-MIN($F$8:$F$11))) | I10: =IF(MAX($G$8:$G$11)=MIN($G$8:$G$11),0,(G10-MIN($G$8:$G$11))/(MAX($G$8:$G$11)-MIN($G$8:$G$11))) | J10: =0.5*H10+0.5*I10 | K10: =0.25*H10+0.75*I10 | L10: =0.75*H10+0.25*I10 | M10: =COUNTIF($J$8:$J$11,"<"&J10)+1
A11: =DECISION_MATRIX!A11 | B11: =IF(MAX(DECISION_MATRIX!$B$8:$B$11)=MIN(DECISION_MATRIX!$B$8:$B$11),0,(DECISION_MATRIX!B11-MIN(DECISION_MATRIX!$B$8:$B$11))/(MAX(DECISION_MATRIX!$B$8:$B$11)-MIN(DECISION_MATRIX!$B$8:$B$11))*WEIGHTS!B19) | C11: =IF(MAX(DECISION_MATRIX!$C$8:$C$11)=MIN(DECISION_MATRIX!$C$8:$C$11),0,(DECISION_MATRIX!C11-MIN(DECISION_MATRIX!$C$8:$C$11))/(MAX(DECISION_MATRIX!$C$8:$C$11)-MIN(DECISION_MATRIX!$C$8:$C$11))*WEIGHTS!C19) | D11: =IF(MAX(DECISION_MATRIX!$D$8:$D$11)=MIN(DECISION_MATRIX!$D$8:$D$11),0,(DECISION_MATRIX!D11-MIN(DECISION_MATRIX!$D$8:$D$11))/(MAX(DECISION_MATRIX!$D$8:$D$11)-MIN(DECISION_MATRIX!$D$8:$D$11))*WEIGHTS!D19) | E11: =IF(MAX(DECISION_MATRIX!$E$8:$E$11)=MIN(DECISION_MATRIX!$E$8:$E$11),0,(DECISION_MATRIX!E11-MIN(DECISION_MATRIX!$E$8:$E$11))/(MAX(DECISION_MATRIX!$E$8:$E$11)-MIN(DECISION_MATRIX!$E$8:$E$11))*WEIGHTS!E19) | F11: =SUM(B11:E11) | G11: =MAX(B11:E11) | H11: =IF(MAX($F$8:$F$11)=MIN($F$8:$F$11),0,(F11-MIN($F$8:$F$11))/(MAX($F$8:$F$11)-MIN($F$8:$F$11))) | I11: =IF(MAX($G$8:$G$11)=MIN($G$8:$G$11),0,(G11-MIN($G$8:$G$11))/(MAX($G$8:$G$11)-MIN($G$8:$G$11))) | J11: =0.5*H11+0.5*I11 | K11: =0.25*H11+0.75*I11 | L11: =0.75*H11+0.25*I11 | M11: =COUNTIF($J$8:$J$11,"<"&J11)+1
A14: Primary SAW choice | B14: =MCDM_CALCULATION!B22
A15: VIKOR first | B15: =INDEX(A8:A11,MATCH(MIN(J8:J11),J8:J11,0))
A16: First row index | B16: =MATCH(B15,A8:A11,0)
A17: DQ threshold | B17: =MIN(0.25,1/(COUNT(J8:J11)-1))
A18: Sufficient advantage? | B18: =SMALL(J8:J11,2)-MIN(J8:J11)>=B17-0.000000000001
A19: Sufficient stability? | B19: =OR(INDEX(F8:F11,B16)<=MIN(F8:F11)+0.000000000001,INDEX(G8:G11,B16)<=MIN(G8:G11)+0.000000000001,AND(INDEX(K8:K11,B16)<=MIN(K8:K11)+0.000000000001,INDEX(L8:L11,B16)<=MIN(L8:L11)+0.000000000001))
A22: Policy | B22: Q score | C22: Compromise member? | D22: Interpretation
A23: =A8 | B23: =J8 | C23: =IF(AND($B$18,$B$19),A23=$B$15,IF(NOT($B$18),B23-MIN($J$8:$J$11)<$B$17,B23<=SMALL($J$8:$J$11,2))) | D23: If acceptance fails, show the compromise set rather than a unique winner.
A24: =A9 | B24: =J9 | C24: =IF(AND($B$18,$B$19),A24=$B$15,IF(NOT($B$18),B24-MIN($J$8:$J$11)<$B$17,B24<=SMALL($J$8:$J$11,2))) | D24: If acceptance fails, show the compromise set rather than a unique winner.
A25: =A10 | B25: =J10 | C25: =IF(AND($B$18,$B$19),A25=$B$15,IF(NOT($B$18),B25-MIN($J$8:$J$11)<$B$17,B25<=SMALL($J$8:$J$11,2))) | D25: If acceptance fails, show the compromise set rather than a unique winner.
A26: =A11 | B26: =J11 | C26: =IF(AND($B$18,$B$19),A26=$B$15,IF(NOT($B$18),B26-MIN($J$8:$J$11)<$B$17,B26<=SMALL($J$8:$J$11,2))) | D26: If acceptance fails, show the compromise set rather than a unique winner.
A28: SAW in compromise set? | B28: =INDEX(C23:C26,MATCH(B14,A23:A26,0))
A30: Constant-column rule | B30: Zero loss for a constant criterion; zero range in S/R contributes zero. Explicit numerical convention.
A32: TOPSIS / PROMETHEE | B32: Literature comparison only; no unsupported numeric rankings.

Sheet SENSITIVITY
A2: Preferences, criterion sets and TECO allowance
A4: Sensitivity is calculated on development data. No profile is chosen to improve ML test performance.
A5: Development context | B5: =WEIGHTS!B5 | D5: Preference profile | E5: =WEIGHTS!B6
A7: Profile | B7: Time weight | C7: CO2 weight | D7: Distance weight | E7: P95 weight | F7: SP cost | G7: DTT cost | H7: ECO cost | I7: TECO10 cost | J7: Selected policy
A8: =WEIGHTS!A10 | B8: =WEIGHTS!B10 | C8: =WEIGHTS!C10 | D8: =WEIGHTS!D10 | E8: =WEIGHTS!E10 | F8: =SUMPRODUCT($B8:$E8,MCDM_CALCULATION!B8:E8) | G8: =SUMPRODUCT($B8:$E8,MCDM_CALCULATION!B9:E9) | H8: =SUMPRODUCT($B8:$E8,MCDM_CALCULATION!B10:E10) | I8: =SUMPRODUCT($B8:$E8,MCDM_CALCULATION!B11:E11) | J8: =INDEX($F$7:$I$7,1,MATCH(MIN(F8:I8),F8:I8,0))
A9: =WEIGHTS!A11 | B9: =WEIGHTS!B11 | C9: =WEIGHTS!C11 | D9: =WEIGHTS!D11 | E9: =WEIGHTS!E11 | F9: =SUMPRODUCT($B9:$E9,MCDM_CALCULATION!B8:E8) | G9: =SUMPRODUCT($B9:$E9,MCDM_CALCULATION!B9:E9) | H9: =SUMPRODUCT($B9:$E9,MCDM_CALCULATION!B10:E10) | I9: =SUMPRODUCT($B9:$E9,MCDM_CALCULATION!B11:E11) | J9: =INDEX($F$7:$I$7,1,MATCH(MIN(F9:I9),F9:I9,0))
A10: =WEIGHTS!A12 | B10: =WEIGHTS!B12 | C10: =WEIGHTS!C12 | D10: =WEIGHTS!D12 | E10: =WEIGHTS!E12 | F10: =SUMPRODUCT($B10:$E10,MCDM_CALCULATION!B8:E8) | G10: =SUMPRODUCT($B10:$E10,MCDM_CALCULATION!B9:E9) | H10: =SUMPRODUCT($B10:$E10,MCDM_CALCULATION!B10:E10) | I10: =SUMPRODUCT($B10:$E10,MCDM_CALCULATION!B11:E11) | J10: =INDEX($F$7:$I$7,1,MATCH(MIN(F10:I10),F10:I10,0))
A11: =WEIGHTS!A13 | B11: =WEIGHTS!B13 | C11: =WEIGHTS!C13 | D11: =WEIGHTS!D13 | E11: =WEIGHTS!E13 | F11: =SUMPRODUCT($B11:$E11,MCDM_CALCULATION!B8:E8) | G11: =SUMPRODUCT($B11:$E11,MCDM_CALCULATION!B9:E9) | H11: =SUMPRODUCT($B11:$E11,MCDM_CALCULATION!B10:E10) | I11: =SUMPRODUCT($B11:$E11,MCDM_CALCULATION!B11:E11) | J11: =INDEX($F$7:$I$7,1,MATCH(MIN(F11:I11),F11:I11,0))
A12: =WEIGHTS!A14 | B12: =WEIGHTS!B14 | C12: =WEIGHTS!C14 | D12: =WEIGHTS!D14 | E12: =WEIGHTS!E14 | F12: =SUMPRODUCT($B12:$E12,MCDM_CALCULATION!B8:E8) | G12: =SUMPRODUCT($B12:$E12,MCDM_CALCULATION!B9:E9) | H12: =SUMPRODUCT($B12:$E12,MCDM_CALCULATION!B10:E10) | I12: =SUMPRODUCT($B12:$E12,MCDM_CALCULATION!B11:E11) | J12: =INDEX($F$7:$I$7,1,MATCH(MIN(F12:I12),F12:I12,0))
A13: =WEIGHTS!A15 | B13: =WEIGHTS!B15 | C13: =WEIGHTS!C15 | D13: =WEIGHTS!D15 | E13: =WEIGHTS!E15 | F13: =SUMPRODUCT($B13:$E13,MCDM_CALCULATION!B8:E8) | G13: =SUMPRODUCT($B13:$E13,MCDM_CALCULATION!B9:E9) | H13: =SUMPRODUCT($B13:$E13,MCDM_CALCULATION!B10:E10) | I13: =SUMPRODUCT($B13:$E13,MCDM_CALCULATION!B11:E11) | J13: =INDEX($F$7:$I$7,1,MATCH(MIN(F13:I13),F13:I13,0))
A17: Time weight | B17: Environment weight | C17: SP | D17: DTT | E17: ECO | F17: TECO10 | G17: Selected policy
A18: 0 | B18: =1-A18 | C18: =A18*MCDM_CALCULATION!B8+B18*MCDM_CALCULATION!C8 | D18: =A18*MCDM_CALCULATION!B9+B18*MCDM_CALCULATION!C9 | E18: =A18*MCDM_CALCULATION!B10+B18*MCDM_CALCULATION!C10 | F18: =A18*MCDM_CALCULATION!B11+B18*MCDM_CALCULATION!C11 | G18: =INDEX($C$17:$F$17,1,MATCH(MIN(C18:F18),C18:F18,0))
A19: 0.05 | B19: =1-A19 | C19: =A19*MCDM_CALCULATION!B8+B19*MCDM_CALCULATION!C8 | D19: =A19*MCDM_CALCULATION!B9+B19*MCDM_CALCULATION!C9 | E19: =A19*MCDM_CALCULATION!B10+B19*MCDM_CALCULATION!C10 | F19: =A19*MCDM_CALCULATION!B11+B19*MCDM_CALCULATION!C11 | G19: =INDEX($C$17:$F$17,1,MATCH(MIN(C19:F19),C19:F19,0))
A20: 0.1 | B20: =1-A20 | C20: =A20*MCDM_CALCULATION!B8+B20*MCDM_CALCULATION!C8 | D20: =A20*MCDM_CALCULATION!B9+B20*MCDM_CALCULATION!C9 | E20: =A20*MCDM_CALCULATION!B10+B20*MCDM_CALCULATION!C10 | F20: =A20*MCDM_CALCULATION!B11+B20*MCDM_CALCULATION!C11 | G20: =INDEX($C$17:$F$17,1,MATCH(MIN(C20:F20),C20:F20,0))
A21: 0.15 | B21: =1-A21 | C21: =A21*MCDM_CALCULATION!B8+B21*MCDM_CALCULATION!C8 | D21: =A21*MCDM_CALCULATION!B9+B21*MCDM_CALCULATION!C9 | E21: =A21*MCDM_CALCULATION!B10+B21*MCDM_CALCULATION!C10 | F21: =A21*MCDM_CALCULATION!B11+B21*MCDM_CALCULATION!C11 | G21: =INDEX($C$17:$F$17,1,MATCH(MIN(C21:F21),C21:F21,0))
A22: 0.2 | B22: =1-A22 | C22: =A22*MCDM_CALCULATION!B8+B22*MCDM_CALCULATION!C8 | D22: =A22*MCDM_CALCULATION!B9+B22*MCDM_CALCULATION!C9 | E22: =A22*MCDM_CALCULATION!B10+B22*MCDM_CALCULATION!C10 | F22: =A22*MCDM_CALCULATION!B11+B22*MCDM_CALCULATION!C11 | G22: =INDEX($C$17:$F$17,1,MATCH(MIN(C22:F22),C22:F22,0))
A23: 0.25 | B23: =1-A23 | C23: =A23*MCDM_CALCULATION!B8+B23*MCDM_CALCULATION!C8 | D23: =A23*MCDM_CALCULATION!B9+B23*MCDM_CALCULATION!C9 | E23: =A23*MCDM_CALCULATION!B10+B23*MCDM_CALCULATION!C10 | F23: =A23*MCDM_CALCULATION!B11+B23*MCDM_CALCULATION!C11 | G23: =INDEX($C$17:$F$17,1,MATCH(MIN(C23:F23),C23:F23,0))
A24: 0.3 | B24: =1-A24 | C24: =A24*MCDM_CALCULATION!B8+B24*MCDM_CALCULATION!C8 | D24: =A24*MCDM_CALCULATION!B9+B24*MCDM_CALCULATION!C9 | E24: =A24*MCDM_CALCULATION!B10+B24*MCDM_CALCULATION!C10 | F24: =A24*MCDM_CALCULATION!B11+B24*MCDM_CALCULATION!C11 | G24: =INDEX($C$17:$F$17,1,MATCH(MIN(C24:F24),C24:F24,0))
A25: 0.35 | B25: =1-A25 | C25: =A25*MCDM_CALCULATION!B8+B25*MCDM_CALCULATION!C8 | D25: =A25*MCDM_CALCULATION!B9+B25*MCDM_CALCULATION!C9 | E25: =A25*MCDM_CALCULATION!B10+B25*MCDM_CALCULATION!C10 | F25: =A25*MCDM_CALCULATION!B11+B25*MCDM_CALCULATION!C11 | G25: =INDEX($C$17:$F$17,1,MATCH(MIN(C25:F25),C25:F25,0))
A26: 0.4 | B26: =1-A26 | C26: =A26*MCDM_CALCULATION!B8+B26*MCDM_CALCULATION!C8 | D26: =A26*MCDM_CALCULATION!B9+B26*MCDM_CALCULATION!C9 | E26: =A26*MCDM_CALCULATION!B10+B26*MCDM_CALCULATION!C10 | F26: =A26*MCDM_CALCULATION!B11+B26*MCDM_CALCULATION!C11 | G26: =INDEX($C$17:$F$17,1,MATCH(MIN(C26:F26),C26:F26,0))
A27: 0.45 | B27: =1-A27 | C27: =A27*MCDM_CALCULATION!B8+B27*MCDM_CALCULATION!C8 | D27: =A27*MCDM_CALCULATION!B9+B27*MCDM_CALCULATION!C9 | E27: =A27*MCDM_CALCULATION!B10+B27*MCDM_CALCULATION!C10 | F27: =A27*MCDM_CALCULATION!B11+B27*MCDM_CALCULATION!C11 | G27: =INDEX($C$17:$F$17,1,MATCH(MIN(C27:F27),C27:F27,0))
A28: 0.5 | B28: =1-A28 | C28: =A28*MCDM_CALCULATION!B8+B28*MCDM_CALCULATION!C8 | D28: =A28*MCDM_CALCULATION!B9+B28*MCDM_CALCULATION!C9 | E28: =A28*MCDM_CALCULATION!B10+B28*MCDM_CALCULATION!C10 | F28: =A28*MCDM_CALCULATION!B11+B28*MCDM_CALCULATION!C11 | G28: =INDEX($C$17:$F$17,1,MATCH(MIN(C28:F28),C28:F28,0))
A29: 0.55 | B29: =1-A29 | C29: =A29*MCDM_CALCULATION!B8+B29*MCDM_CALCULATION!C8 | D29: =A29*MCDM_CALCULATION!B9+B29*MCDM_CALCULATION!C9 | E29: =A29*MCDM_CALCULATION!B10+B29*MCDM_CALCULATION!C10 | F29: =A29*MCDM_CALCULATION!B11+B29*MCDM_CALCULATION!C11 | G29: =INDEX($C$17:$F$17,1,MATCH(MIN(C29:F29),C29:F29,0))
A30: 0.6 | B30: =1-A30 | C30: =A30*MCDM_CALCULATION!B8+B30*MCDM_CALCULATION!C8 | D30: =A30*MCDM_CALCULATION!B9+B30*MCDM_CALCULATION!C9 | E30: =A30*MCDM_CALCULATION!B10+B30*MCDM_CALCULATION!C10 | F30: =A30*MCDM_CALCULATION!B11+B30*MCDM_CALCULATION!C11 | G30: =INDEX($C$17:$F$17,1,MATCH(MIN(C30:F30),C30:F30,0))
A31: 0.65 | B31: =1-A31 | C31: =A31*MCDM_CALCULATION!B8+B31*MCDM_CALCULATION!C8 | D31: =A31*MCDM_CALCULATION!B9+B31*MCDM_CALCULATION!C9 | E31: =A31*MCDM_CALCULATION!B10+B31*MCDM_CALCULATION!C10 | F31: =A31*MCDM_CALCULATION!B11+B31*MCDM_CALCULATION!C11 | G31: =INDEX($C$17:$F$17,1,MATCH(MIN(C31:F31),C31:F31,0))
A32: 0.7 | B32: =1-A32 | C32: =A32*MCDM_CALCULATION!B8+B32*MCDM_CALCULATION!C8 | D32: =A32*MCDM_CALCULATION!B9+B32*MCDM_CALCULATION!C9 | E32: =A32*MCDM_CALCULATION!B10+B32*MCDM_CALCULATION!C10 | F32: =A32*MCDM_CALCULATION!B11+B32*MCDM_CALCULATION!C11 | G32: =INDEX($C$17:$F$17,1,MATCH(MIN(C32:F32),C32:F32,0))
A33: 0.75 | B33: =1-A33 | C33: =A33*MCDM_CALCULATION!B8+B33*MCDM_CALCULATION!C8 | D33: =A33*MCDM_CALCULATION!B9+B33*MCDM_CALCULATION!C9 | E33: =A33*MCDM_CALCULATION!B10+B33*MCDM_CALCULATION!C10 | F33: =A33*MCDM_CALCULATION!B11+B33*MCDM_CALCULATION!C11 | G33: =INDEX($C$17:$F$17,1,MATCH(MIN(C33:F33),C33:F33,0))
A34: 0.8 | B34: =1-A34 | C34: =A34*MCDM_CALCULATION!B8+B34*MCDM_CALCULATION!C8 | D34: =A34*MCDM_CALCULATION!B9+B34*MCDM_CALCULATION!C9 | E34: =A34*MCDM_CALCULATION!B10+B34*MCDM_CALCULATION!C10 | F34: =A34*MCDM_CALCULATION!B11+B34*MCDM_CALCULATION!C11 | G34: =INDEX($C$17:$F$17,1,MATCH(MIN(C34:F34),C34:F34,0))
A35: 0.85 | B35: =1-A35 | C35: =A35*MCDM_CALCULATION!B8+B35*MCDM_CALCULATION!C8 | D35: =A35*MCDM_CALCULATION!B9+B35*MCDM_CALCULATION!C9 | E35: =A35*MCDM_CALCULATION!B10+B35*MCDM_CALCULATION!C10 | F35: =A35*MCDM_CALCULATION!B11+B35*MCDM_CALCULATION!C11 | G35: =INDEX($C$17:$F$17,1,MATCH(MIN(C35:F35),C35:F35,0))
A36: 0.9 | B36: =1-A36 | C36: =A36*MCDM_CALCULATION!B8+B36*MCDM_CALCULATION!C8 | D36: =A36*MCDM_CALCULATION!B9+B36*MCDM_CALCULATION!C9 | E36: =A36*MCDM_CALCULATION!B10+B36*MCDM_CALCULATION!C10 | F36: =A36*MCDM_CALCULATION!B11+B36*MCDM_CALCULATION!C11 | G36: =INDEX($C$17:$F$17,1,MATCH(MIN(C36:F36),C36:F36,0))
A37: 0.95 | B37: =1-A37 | C37: =A37*MCDM_CALCULATION!B8+B37*MCDM_CALCULATION!C8 | D37: =A37*MCDM_CALCULATION!B9+B37*MCDM_CALCULATION!C9 | E37: =A37*MCDM_CALCULATION!B10+B37*MCDM_CALCULATION!C10 | F37: =A37*MCDM_CALCULATION!B11+B37*MCDM_CALCULATION!C11 | G37: =INDEX($C$17:$F$17,1,MATCH(MIN(C37:F37),C37:F37,0))
A38: 1 | B38: =1-A38 | C38: =A38*MCDM_CALCULATION!B8+B38*MCDM_CALCULATION!C8 | D38: =A38*MCDM_CALCULATION!B9+B38*MCDM_CALCULATION!C9 | E38: =A38*MCDM_CALCULATION!B10+B38*MCDM_CALCULATION!C10 | F38: =A38*MCDM_CALCULATION!B11+B38*MCDM_CALCULATION!C11 | G38: =INDEX($C$17:$F$17,1,MATCH(MIN(C38:F38),C38:F38,0))
A43: TECO setting | B43: Mean time (s) | C43: Mean CO2 (g) | D43: Mean P95 (s) | E43: CO2 WAPE, run mean | F43: Realized above predicted time bound
A44: TECO05 | B44: 475.66715 | C44: 1197.7508 | D44: 672.75694 | E44: 0.15482071 | F44: 0.54121055
A45: TECO10 | B45: 564.93316 | C45: 1268.2908 | D45: 800.89792 | E45: 0.12827788 | F45: 0.35551597
A46: TECO15 | B46: 590.31772 | C46: 1349.4213 | D46: 834.88472 | E46: 0.12131926 | F46: 0.26133454
A49: TECO interpretation | B49: These are observed development effects, not guaranteed realized detour bounds. No final alpha is frozen.
A52: Full-design diagnostic | B52: Balanced / time-heavy / environment-heavy winners are identical in all 24 contexts.
A54: Broad 0..1 sweep | B54: Only 1 of 24 contexts changes winner over the 0.05-spaced two-criterion weight sweep.
A56: Third criteria | B56: Distance-set changes 0/24 balanced choices; Tail-set changes 1/24.

Sheet ML_SELECTION
A2: New selector is NOT FITTED
A4: Main release is blocked by route-order validation; these cells are deliberately not invented predictions.
A7: Stage | B7: Context count | C7: Role | D7: Model status | E7: Evidence
A8: Pilot | B8: 30 | C8: 21 training / 9 test; frozen historical model | D8: ALREADY COMPLETED | E8: Always DTT; no positive adaptive gain
A9: Current development | B9: 24 | C9: Engineering / complementarity diagnostics | D9: NOT USED TO CLAIM TEST GAIN | E9: 432 runs + separate route probes
A10: Candidate main training | B10: 84 | C10: Fit scaled multi-output CART | D10: TO BE GENERATED | E10: No new main data
A11: Candidate validation | B11: 28 | C11: One prespecified model check / lock | D11: TO BE GENERATED | E11: Do not alter test from this result
A12: Candidate test | B12: 28 | C12: One held-out observed decision evaluation | D12: TO BE GENERATED | E12: No new predictions or losses
A16: Feature | B16: Available when? | C16: Encoding | D16: Leakage restriction
A17: Primary demand | B17: Scheduled before episode | C17: Numeric veh/h | D17: No future realized demand outcome
A18: Background per stream | B18: Scheduled before episode | C18: Numeric veh/h | D18: Same manifest across compared policies
A19: Restriction location | B19: Known planned restriction | C19: One-hot location | D19: Unannounced incidents require separate detection study
A20: Restriction speed ratio | B20: Known planned control | C20: Numeric 0.35/0.65 or1 | D20: No future realized queue
A21: Signal regime | B21: Controller plan known | C21: Binary regime | D21: No realized travel times/emissions
A24: Recommended task | B24: Predict all policy outcomes; apply the same frozen preferences to predictions; evaluate chosen policy on observed test outcomes.
A27: Recommended model | B27: CART depth3, min leaf8, training-only scaled outputs. Constant training-mean prediction baseline.
A30: Why regression? | B30: Reusable across declared weights; direct labels conflate preferences and physical prediction.
A33: Grouping | B33: All replications of a context together. 140 contexts remain 140 ML examples, not 2,800.
A36: Test meaning | B36: Held-out factor combinations in the same synthetic network/range; not city transfer or out-of-range extrapolation.

Sheet ROBUSTNESS
A2: Descriptive development headroom; no new ML result
A4: Fixed and oracle calculated on the same development matrix: descriptive opportunity, NOT held-out performance.
A7: Context | B7: SP cost | C7: DTT cost | D7: ECO cost | E7: TECO10 cost | F7: Oracle cost | G7: SP regret | H7: DTT regret | I7: ECO regret | J7: TECO10 regret | K7: Winner | L7: Fixed DTT headroom
A8: D001 | B8: =REDESIGN_RESULTS!D8/WEIGHTS!$B$22*WEIGHTS!$B$19+REDESIGN_RESULTS!E8/WEIGHTS!$C$22*WEIGHTS!$C$19+REDESIGN_RESULTS!F8/WEIGHTS!$D$22*WEIGHTS!$D$19+REDESIGN_RESULTS!G8/WEIGHTS!$E$22*WEIGHTS!$E$19 | C8: =REDESIGN_RESULTS!D9/WEIGHTS!$B$22*WEIGHTS!$B$19+REDESIGN_RESULTS!E9/WEIGHTS!$C$22*WEIGHTS!$C$19+REDESIGN_RESULTS!F9/WEIGHTS!$D$22*WEIGHTS!$D$19+REDESIGN_RESULTS!G9/WEIGHTS!$E$22*WEIGHTS!$E$19 | D8: =REDESIGN_RESULTS!D10/WEIGHTS!$B$22*WEIGHTS!$B$19+REDESIGN_RESULTS!E10/WEIGHTS!$C$22*WEIGHTS!$C$19+REDESIGN_RESULTS!F10/WEIGHTS!$D$22*WEIGHTS!$D$19+REDESIGN_RESULTS!G10/WEIGHTS!$E$22*WEIGHTS!$E$19 | E8: =REDESIGN_RESULTS!D12/WEIGHTS!$B$22*WEIGHTS!$B$19+REDESIGN_RESULTS!E12/WEIGHTS!$C$22*WEIGHTS!$C$19+REDESIGN_RESULTS!F12/WEIGHTS!$D$22*WEIGHTS!$D$19+REDESIGN_RESULTS!G12/WEIGHTS!$E$22*WEIGHTS!$E$19 | F8: =MIN(B8:E8) | G8: =B8-F8 | H8: =C8-F8 | I8: =D8-F8 | J8: =E8-F8 | K8: =INDEX($B$7:$E$7,1,MATCH(F8,B8:E8,0)) | L8: =H8
A9: D002 | B9: =REDESIGN_RESULTS!D14/WEIGHTS!$B$22*WEIGHTS!$B$19+REDESIGN_RESULTS!E14/WEIGHTS!$C$22*WEIGHTS!$C$19+REDESIGN_RESULTS!F14/WEIGHTS!$D$22*WEIGHTS!$D$19+REDESIGN_RESULTS!G14/WEIGHTS!$E$22*WEIGHTS!$E$19 | C9: =REDESIGN_RESULTS!D15/WEIGHTS!$B$22*WEIGHTS!$B$19+REDESIGN_RESULTS!E15/WEIGHTS!$C$22*WEIGHTS!$C$19+REDESIGN_RESULTS!F15/WEIGHTS!$D$22*WEIGHTS!$D$19+REDESIGN_RESULTS!G15/WEIGHTS!$E$22*WEIGHTS!$E$19 | D9: =REDESIGN_RESULTS!D16/WEIGHTS!$B$22*WEIGHTS!$B$19+REDESIGN_RESULTS!E16/WEIGHTS!$C$22*WEIGHTS!$C$19+REDESIGN_RESULTS!F16/WEIGHTS!$D$22*WEIGHTS!$D$19+REDESIGN_RESULTS!G16/WEIGHTS!$E$22*WEIGHTS!$E$19 | E9: =REDESIGN_RESULTS!D18/WEIGHTS!$B$22*WEIGHTS!$B$19+REDESIGN_RESULTS!E18/WEIGHTS!$C$22*WEIGHTS!$C$19+REDESIGN_RESULTS!F18/WEIGHTS!$D$22*WEIGHTS!$D$19+REDESIGN_RESULTS!G18/WEIGHTS!$E$22*WEIGHTS!$E$19 | F9: =MIN(B9:E9) | G9: =B9-F9 | H9: =C9-F9 | I9: =D9-F9 | J9: =E9-F9 | K9: =INDEX($B$7:$E$7,1,MATCH(F9,B9:E9,0)) | L9: =H9
A10: D003 | B10: =REDESIGN_RESULTS!D20/WEIGHTS!$B$22*WEIGHTS!$B$19+REDESIGN_RESULTS!E20/WEIGHTS!$C$22*WEIGHTS!$C$19+REDESIGN_RESULTS!F20/WEIGHTS!$D$22*WEIGHTS!$D$19+REDESIGN_RESULTS!G20/WEIGHTS!$E$22*WEIGHTS!$E$19 | C10: =REDESIGN_RESULTS!D21/WEIGHTS!$B$22*WEIGHTS!$B$19+REDESIGN_RESULTS!E21/WEIGHTS!$C$22*WEIGHTS!$C$19+REDESIGN_RESULTS!F21/WEIGHTS!$D$22*WEIGHTS!$D$19+REDESIGN_RESULTS!G21/WEIGHTS!$E$22*WEIGHTS!$E$19 | D10: =REDESIGN_RESULTS!D22/WEIGHTS!$B$22*WEIGHTS!$B$19+REDESIGN_RESULTS!E22/WEIGHTS!$C$22*WEIGHTS!$C$19+REDESIGN_RESULTS!F22/WEIGHTS!$D$22*WEIGHTS!$D$19+REDESIGN_RESULTS!G22/WEIGHTS!$E$22*WEIGHTS!$E$19 | E10: =REDESIGN_RESULTS!D24/WEIGHTS!$B$22*WEIGHTS!$B$19+REDESIGN_RESULTS!E24/WEIGHTS!$C$22*WEIGHTS!$C$19+REDESIGN_RESULTS!F24/WEIGHTS!$D$22*WEIGHTS!$D$19+REDESIGN_RESULTS!G24/WEIGHTS!$E$22*WEIGHTS!$E$19 | F10: =MIN(B10:E10) | G10: =B10-F10 | H10: =C10-F10 | I10: =D10-F10 | J10: =E10-F10 | K10: =INDEX($B$7:$E$7,1,MATCH(F10,B10:E10,0)) | L10: =H10
A11: D004 | B11: =REDESIGN_RESULTS!D26/WEIGHTS!$B$22*WEIGHTS!$B$19+REDESIGN_RESULTS!E26/WEIGHTS!$C$22*WEIGHTS!$C$19+REDESIGN_RESULTS!F26/WEIGHTS!$D$22*WEIGHTS!$D$19+REDESIGN_RESULTS!G26/WEIGHTS!$E$22*WEIGHTS!$E$19 | C11: =REDESIGN_RESULTS!D27/WEIGHTS!$B$22*WEIGHTS!$B$19+REDESIGN_RESULTS!E27/WEIGHTS!$C$22*WEIGHTS!$C$19+REDESIGN_RESULTS!F27/WEIGHTS!$D$22*WEIGHTS!$D$19+REDESIGN_RESULTS!G27/WEIGHTS!$E$22*WEIGHTS!$E$19 | D11: =REDESIGN_RESULTS!D28/WEIGHTS!$B$22*WEIGHTS!$B$19+REDESIGN_RESULTS!E28/WEIGHTS!$C$22*WEIGHTS!$C$19+REDESIGN_RESULTS!F28/WEIGHTS!$D$22*WEIGHTS!$D$19+REDESIGN_RESULTS!G28/WEIGHTS!$E$22*WEIGHTS!$E$19 | E11: =REDESIGN_RESULTS!D30/WEIGHTS!$B$22*WEIGHTS!$B$19+REDESIGN_RESULTS!E30/WEIGHTS!$C$22*WEIGHTS!$C$19+REDESIGN_RESULTS!F30/WEIGHTS!$D$22*WEIGHTS!$D$19+REDESIGN_RESULTS!G30/WEIGHTS!$E$22*WEIGHTS!$E$19 | F11: =MIN(B11:E11) | G11: =B11-F11 | H11: =C11-F11 | I11: =D11-F11 | J11: =E11-F11 | K11: =INDEX($B$7:$E$7,1,MATCH(F11,B11:E11,0)) | L11: =H11
A12: D005 | B12: =REDESIGN_RESULTS!D32/WEIGHTS!$B$22*WEIGHTS!$B$19+REDESIGN_RESULTS!E32/WEIGHTS!$C$22*WEIGHTS!$C$19+REDESIGN_RESULTS!F32/WEIGHTS!$D$22*WEIGHTS!$D$19+REDESIGN_RESULTS!G32/WEIGHTS!$E$22*WEIGHTS!$E$19 | C12: =REDESIGN_RESULTS!D33/WEIGHTS!$B$22*WEIGHTS!$B$19+REDESIGN_RESULTS!E33/WEIGHTS!$C$22*WEIGHTS!$C$19+REDESIGN_RESULTS!F33/WEIGHTS!$D$22*WEIGHTS!$D$19+REDESIGN_RESULTS!G33/WEIGHTS!$E$22*WEIGHTS!$E$19 | D12: =REDESIGN_RESULTS!D34/WEIGHTS!$B$22*WEIGHTS!$B$19+REDESIGN_RESULTS!E34/WEIGHTS!$C$22*WEIGHTS!$C$19+REDESIGN_RESULTS!F34/WEIGHTS!$D$22*WEIGHTS!$D$19+REDESIGN_RESULTS!G34/WEIGHTS!$E$22*WEIGHTS!$E$19 | E12: =REDESIGN_RESULTS!D36/WEIGHTS!$B$22*WEIGHTS!$B$19+REDESIGN_RESULTS!E36/WEIGHTS!$C$22*WEIGHTS!$C$19+REDESIGN_RESULTS!F36/WEIGHTS!$D$22*WEIGHTS!$D$19+REDESIGN_RESULTS!G36/WEIGHTS!$E$22*WEIGHTS!$E$19 | F12: =MIN(B12:E12) | G12: =B12-F12 | H12: =C12-F12 | I12: =D12-F12 | J12: =E12-F12 | K12: =INDEX($B$7:$E$7,1,MATCH(F12,B12:E12,0)) | L12: =H12
